Workbook

Sheet Randomization_Info
A1: PatientID | B1: Sex | C1: Baseline_Age | D1: Randomized | E1: Excl_Reason | F1: Tx_Arm | G1: Tx_Received | H1: Follow_Up | I1: Analyzed
A2: 101 | B2: M | C2: 52 | D2: 0 | E2: 3
A3: 102 | B3: F | C3: 31 | D3: 0 | E3: 1 | K3: VLOOKUP(A2,Demographics.xlsx!$A:$B,2,FALSE)
A4: 103 | B4: F | C4: 46 | D4: 0 | E4: 1
A5: 105 | B5: M | C5: 28 | D5: 1 | F5: A | G5: 1 | I5: 1
A6: 106 | B6: F | C6: 38 | D6: 1 | F6: B | G6: 1 | I6: 1 | K6: VLOOKUP(A2,Demographics.xlsx!$A:$C,3,FALSE)
A7: 107 | B7: F | C7: 35 | D7: 0 | E7: 2
A8: 108 | B8: F | C8: 27 | D8: 0 | E8: 1
A9: 109 | B9: M | C9: 19 | D9: 0 | E9: 1
A10: 110 | B10: M | C10: 33 | D10: 1 | F10: B | G10: 1 | I10: 1
A11: 111 | B11: F | C11: 30 | D11: 1 | F11: B | G11: 1 | I11: 1
A12: 113 | B12: M | C12: 35 | D12: 1 | F12: B | G12: 1 | I12: 1
A13: 114 | B13: M | C13: 47 | D13: 0 | E13: 1
A14: 115 | B14: F | C14: 52 | D14: 1 | F14: B | G14: 1 | I14: 1
A15: 116 | B15: M | C15: 48 | D15: 0 | E15: 3
A16: 117 | B16: M | C16: 52 | D16: 0 | E16: 3
A17: 118 | B17: F | C17: 34 | D17: 1 | F17: A | G17: 1 | I17: 1
A18: 120 | B18: F | C18: 22 | D18: 0 | E18: 2
A19: 121 | B19: F | C19: 53 | D19: 1 | F19: B | G19: 0 | I19: 1
A20: 122 | B20: M | C20: 34 | D20: 0 | E20: 1
A21: 123 | B21: M | C21: 36 | D21: 0 | E21: 1
A22: 124 | B22: F | C22: 53 | D22: 0 | E22: 2
A23: 125 | B23: M | C23: 37 | D23: 1 | F23: B | G23: 1 | I23: 1
A24: 126 | B24: M | C24: 44 | D24: 0 | E24: 3
A25: 127 | B25: F | C25: 45 | D25: 0 | E25: 1
A26: 128 | B26: F | C26: 46 | D26: 1 | F26: A | G26: 1 | I26: 1
A27: 129 | B27: F | C27: 47 | D27: 1 | F27: A | G27: 1 | I27: 1
A28: 130 | B28: F | C28: 40 | D28: 0 | E28: 1
A29: 131 | B29: M | C29: 41 | D29: 0 | E29: 1
A30: 132 | B30: F | C30: 20 | D30: 0 | E30: 1
A31: 134 | B31: M | C31: 37 | D31: 1 | F31: A | G31: 1 | I31: 1
A32: 135 | B32: F | C32: 25 | D32: 1 | F32: A | G32: 1 | I32: 1
A33: 136 | B33: F | C33: 40 | D33: 1 | F33: B | G33: 1 | I33: 1
A34: 137 | B34: M | C34: 26 | D34: 0 | E34: 3
A35: 138 | B35: M | C35: 18 | D35: 0 | E35: 2
A36: 139 | B36: M | C36: 47 | D36: 1 | F36: B | G36: 1 | H36: 2 | I36: 1
A37: 140 | B37: F | C37: 54 | D37: 0 | E37: 1
A38: 141 | B38: M | C38: 48 | D38: 0 | E38: 2
A39: 142 | B39: M | C39: 38 | D39: 0 | E39: 2
A40: 143 | B40: F | C40: 23 | D40: 0 | E40: 2
...

Sheet CONSORT
G2: Assessed for Eligibility
G3: =COUNT(Randomization_Info!A2:A180) -> 179
J5: Excluded (Not Randomized) | K5: =COUNTIF(Randomization_Info!D2:D180,0) -> 90
J6: Not Meeting Inclusion Criteria | K6: =COUNTIFS(Randomization_Info!$D$2:$D$180,0,Randomization_Info!$E$2:$E$180,1) -> 38
J7: Refused to Participate | K7: =COUNTIFS(Randomization_Info!$D$2:$D$180,0,Randomization_Info!$E$2:$E$180, 2) -> 18
J8: Other Reasons | K8: =COUNTIFS(Randomization_Info!$D$2:$D$180,0,Randomization_Info!$E$2:$E$180,3) + COUNTIFS(Randomization_Info!$D$2:$D$180,0,Randomization_Info!$E$2:$E$180,4) + COUNTIFS(Randomization_Info!$D$2:$D$180,0,Randomization_Info!$E$2:$E$180,5) -> 34
G12: Randomized
G13: =COUNTIF(Randomization_Info!D2:D180, 1) -> 89
C15: Treatment A (Experimental) | J15: Treatment B (Standard of Care)
C16: Allocated to Intervention (Total) | E16: =COUNTIFS(Randomization_Info!$D$2:$D$180,1,Randomization_Info!$F$2:$F$180,"A") -> 44 | J16: Allocated to Intervention (Total) | L16: =COUNTIFS(Randomization_Info!$D$2:$D$180,1,Randomization_Info!$F$2:$F$180,"B") -> 45
D17: Received Allocated Intervention | E17: =COUNTIFS(Randomization_Info!$D$2:$D$180,1,Randomization_Info!$F$2:$F$180,"A", Randomization_Info!$G$2:$G$180,1) -> 43 | K17: Received Allocated Intervention | L17: =COUNTIFS(Randomization_Info!$D$2:$D$180,1,Randomization_Info!$F$2:$F$180,"B", Randomization_Info!$G$2:$G$180,1) -> 43
D18: Did not Receive Allocated Intervention | E18: =COUNTIFS(Randomization_Info!$D$2:$D$180,1,Randomization_Info!$F$2:$F$180,"A", Randomization_Info!$G$2:$G$180, 0) -> 1 | K18: Did not Receive Allocated Intervention | L18: =COUNTIFS(Randomization_Info!$D$2:$D$180,1,Randomization_Info!$F$2:$F$180,"B", Randomization_Info!$G$2:$G$180,0) -> 2
C24: Follow-Up | J24: Follow-Up
D25: Lost to Follow-Up | E25: =COUNTIFS(Randomization_Info!$H$2:$H$180,1,Randomization_Info!$D$2:$D$180,1,Randomization_Info!$F$2:$F$180,"A",Randomization_Info!$G$2:$G$180,1) -> 2 | K25: Lost to Follow-Up | L25: =COUNTIFS(Randomization_Info!$H$2:$H$180,1,Randomization_Info!$D$2:$D$180,1,Randomization_Info!$F$2:$F$180,"B",Randomization_Info!$G$2:$G$180,1) -> 1
D26: Discontinued Intervention | E26: =COUNTIFS(Randomization_Info!$H$2:$H$180,2,Randomization_Info!$D$2:$D$180,1,Randomization_Info!$F$2:$F$180,"A",Randomization_Info!$G$2:$G$180,1) -> 1 | K26: Discontinued Intervention | L26: =COUNTIFS(Randomization_Info!$H$2:$H$180,2,Randomization_Info!$D$2:$D$180,1,Randomization_Info!$F$2:$F$180,"B",Randomization_Info!$G$2:$G$180,1) -> 1
C32: Analysis | J32: Analysis
D33: Analyzed | E33: =COUNTIFS(Randomization_Info!$I$2:$I$180,1,Randomization_Info!$D$2:$D$180,1,Randomization_Info!$F$2:$F$180,"A") -> 44 | K33: Analyzed | L33: =COUNTIFS(Randomization_Info!$I$2:$I$180,1,Randomization_Info!$D$2:$D$180,1,Randomization_Info!$F$2:$F$180,"B") -> 44
D34: Excluded from Analysis | E34: =COUNTIFS(Randomization_Info!$I$2:$I$180,0,Randomization_Info!$D$2:$D$180,1,Randomization_Info!$F$2:$F$180,"A") -> 0 | K34: Excluded from Analysis | L34: =COUNTIFS(Randomization_Info!$I$2:$I$180,0,Randomization_Info!$D$2:$D$180,1,Randomization_Info!$F$2:$F$180,"B") -> 1
C39: Descriptive Statistics for Analyzed Patients | J39: Descriptive Statistics for Analyzed Patients
D40: N | E40: Mean Age at Baseline (Years) | K40: N | L40: Mean Age at Baseline (Years)
C42: Males | D42: =COUNTIFS(Randomization_Info!$B$2:$B$180,"M",Randomization_Info!$D$2:$D$180,1,Randomization_Info!$F$2:$F$180,"A",Randomization_Info!$I$2:$I$180,1) -> 23 | E42: =AVERAGEIFS(Randomization_Info!$C$2:$C$180,Randomization_Info!$B$2:$B$180,"M",Randomization_Info!$D$2:$D$180,1,Randomization_Info!$F$2:$F$180,"A",Randomization_Info!$I$2:$I$180,1) -> 35.304348 | J42: Males | K42: =COUNTIFS(Randomization_Info!$B$2:$B$180,"M",Randomization_Info!$D$2:$D$180,1,Randomization_Info!$F$2:$F$180,"B",Randomization_Info!$I$2:$I$180,1) -> 22 | L42: =AVERAGEIFS(Randomization_Info!$C$2:$C$180,Randomization_Info!$B$2:$B$180,"M",Randomization_Info!$D$2:$D$180,1,Randomization_Info!$F$2:$F$180,"B",Randomization_Info!$I$2:$I$180,1) -> 37.363636
C43: Females | D43: =COUNTIFS(Randomization_Info!$B$2:$B$180,"F",Randomization_Info!$D$2:$D$180,1,Randomization_Info!$F$2:$F$180,"A",Randomization_Info!$I$2:$I$180,1) -> 21 | E43: =AVERAGEIFS(Randomization_Info!$C$2:$C$180,Randomization_Info!$B$2:$B$180,"F",Randomization_Info!$D$2:$D$180,1,Randomization_Info!$F$2:$F$180,"A",Randomization_Info!$I$2:$I$180,1) -> 39.190476 | J43: Females | K43: =COUNTIFS(Randomization_Info!$B$2:$B$180,"F",Randomization_Info!$D$2:$D$180,1,Randomization_Info!$F$2:$F$180,"B",Randomization_Info!$I$2:$I$180,1) -> 22 | L43: =AVERAGEIFS(Randomization_Info!$C$2:$C$180,Randomization_Info!$B$2:$B$180,"F",Randomization_Info!$D$2:$D$180,1,Randomization_Info!$F$2:$F$180,"B",Randomization_Info!$I$2:$I$180,1) -> 39.363636
